Workbook

Sheet Summary Menu
A1: Summary Menu
A2: Menu | B2: COGS | C2: Selling Price | D2: =IFERROR(B2/C2,0) -> 0 | E2: Status | F2: Description
A3: Yakitori Stall | B3: =IFERROR(AVERAGE(B4:B9),0) -> 8334.496 | C3: =IFERROR(AVERAGE(C4:C9),0) -> 21666.667 | D3: =IFERROR(B3/C3,0) -> 0.38466905
A4: Negima | B4: ='Yakitori Stall'!E15 -> 8712.2285 | C4: ='Yakitori Stall'!E18 -> 20000 | D4: =IFERROR(B4/C4,0) -> 0.43561142 | E4: Recipe Available | F4: Chicken thigh with leek and soy tare
A5: Tsukune | B5: ='Yakitori Stall'!E33 -> 10772.127 | C5: ='Yakitori Stall'!E36 -> 25000 | D5: =IFERROR(B5/C5,0) -> 0.43088507 | E5: Recipe Available | F5: chicken meat ball served with soy tare
A6: Torikawa | B6: ='Yakitori Stall'!E51 -> 5733.7285 | C6: ='Yakitori Stall'!E54 -> 15000 | D6: =IFERROR(B6/C6,0) -> 0.38224857 | E6: Recipe Available | F6: Crispy Chicken skin with salt
A7: Tebasaki | B7: ='Yakitori Stall'!E69 -> 7362.8952 | C7: ='Yakitori Stall'!E72 -> 20000 | D7: =IFERROR(B7/C7,0) -> 0.36814476 | E7: Recipe Available | F7: Chicken wings
A8: Beef Enoki Roll | B8: ='Yakitori Stall'!E87 -> 8666.2285 | C8: ='Yakitori Stall'!E90 -> 25000 | D8: =IFERROR(B8/C8,0) -> 0.34664914 | E8: Recipe Available | F8: Enoki mushroom wrapped with USDA shortplate beef
A9: Beef Mochi | B9: ='Yakitori Stall'!E105 -> 8759.7686 | C9: ='Yakitori Stall'!E108 -> 25000 | D9: =IFERROR(B9/C9,0) -> 0.35039075 | E9: Recipe Available | F9: Chewy mochi wrapped with USDA shortplate beef
A11: Teppanyaki Stall | B11: =IFERROR(AVERAGE(B12:B16),0) -> 7552.4294 | C11: =IFERROR(AVERAGE(C12:C16),0) -> 61000 | D11: =IFERROR(B11/C11,0) -> 0.12381032
A12: Takoyaki | B12: ='Teppanyaki Stall '!E18 -> 16487.147 | C12: ='Teppanyaki Stall '!E21 -> 60000 | D12: =IFERROR(B12/C12,0) -> 0.27478579 | E12: Recipe Pending | F12: Classic takoyaki with condiment
A13: Yasai Itame | B13: ='Teppanyaki Stall '!E36 -> 0 | C13: ='Teppanyaki Stall '!E39 -> 65000 | D13: =IFERROR(B13/C13,0) -> 0 | E13: Recipe Pending | F13: Stir-fry mix vegetables with usda beef topping with katsuobushi
A14: Ika Sugatayaki | B14: ='Teppanyaki Stall '!E54 -> 21275 | C14: ='Teppanyaki Stall '!E57 -> 55000 | D14: =IFERROR(B14/C14,0) -> 0.38681818 | E14: Recipe Pending | F14: grilled fresh squid served with shoyu tare
A15: Ika Okonomiyaki | B15: ='Teppanyaki Stall '!E72 -> 0 | C15: ='Teppanyaki Stall '!E75 -> 60000 | D15: =IFERROR(B15/C15,0) -> 0 | E15: Recipe Pending | F15: Osaka style okonomiyaki served with grilled squid
A16: Beef Okonomiyaki | B16: ='Teppanyaki Stall '!E90 -> 0 | C16: ='Teppanyaki Stall '!E93 -> 65000 | D16: =IFERROR(B16/C16,0) -> 0 | E16: Recipe Pending | F16: Osaka style okonomiyaki served with grilled beef
A18: Dumpling Stall | B18: =IFERROR(AVERAGE(B19:B23),0) -> 9895.1602 | C18: =IFERROR(AVERAGE(C19:C23),0) -> 31000 | D18: =IFERROR(B18/C18,0) -> 0.31919872
A19: Okonomiyaki Gyoza | B19: ='Dumpling Stall'!E15 -> 12606.184 | C19: ='Dumpling Stall'!E18 -> 35000 | D19: =IFERROR(B19/C19,0) -> 0.3601767 | E19: Recipe Available | F19: seared japanese dumpling,crispy tuille,okonomiyaki sauce and katsuobushi
A20: Slider Gyoza Mentai | B20: ='Dumpling Stall'!E33 -> 11933.94 | C20: ='Dumpling Stall'!E36 -> 35000 | D20: =IFERROR(B20/C20,0) -> 0.34096971 | E20: Recipe Available | F20: Deep fried japanese dumpling served creamy mentaiko sauce
A21: Spicy Tteokboki Gyoza | B21: ='Dumpling Stall'!E51 -> 17929.966 | C21: ='Dumpling Stall'!E54 -> 35000 | D21: =IFERROR(B21/C21,0) -> 0.51228475 | E21: Recipe Available | F21: steam gyoza served with spicy and creamy miso tteokboki
A22: Yaki Gyoza | B22: ='Dumpling Stall'!E69 -> 3439.765 | C22: ='Dumpling Stall'!E72 -> 25000 | D22: =IFERROR(B22/C22,0) -> 0.1375906 | E22: Recipe Pending | F22: Pan seared Japanese chicken dumpling
A23: Age Gyoza | B23: ='Dumpling Stall'!E87 -> 3565.9456 | C23: ='Dumpling Stall'!E90 -> 25000 | D23: =IFERROR(B23/C23,0) -> 0.14263782 | E23: Recipe Pending | F23: Deep fried japanese chicken dumpling
A25: Sushi - Sashimi Stall | B25: =IFERROR(AVERAGE(B26:B39),0) -> 56386.936 | C25: =IFERROR(AVERAGE(C26:C39),0) -> 78333.333 | D25: =IFERROR(B25/C25,0) -> 0.71983322
A26: Tamagoyaki Mentai | B26: ='Sushi - Sashimi Stall'!E15 -> 8605.9571 | C26: ='Sushi - Sashimi Stall'!E18 | D26: =IFERROR(B26/C26,0) -> 0 | E26: Recipe Pending | F26: Sweet Japanese omelette egg served with creamy mentai mayo
A27: Tuna Wasabi Mayo Taco | B27: ='Sushi - Sashimi Stall'!E33 -> 11582.417 | C27: ='Sushi - Sashimi Stall'!E36 | D27: =IFERROR(B27/C27,0) -> 0 | E27: Recipe Pending | F27: cube fresh tuna mixwd with creamy wasabi mayo and wrapped with crispy nori
A28: Unagi Nigiri | B28: ='Sushi - Sashimi Stall'!E51 -> 48519.545 | C28: 65000 | D28: =IFERROR(B28/C28,0) -> 0.74645455 | E28: Recipe Pending | F28: Sushi rice on top grilled uangi
A29: Chuka Idako Gunkan | B29: ='Sushi - Sashimi Stall'!E69 -> 0 | C29: ='Sushi - Sashimi Stall'!E72 | D29: =IFERROR(B29/C29,0) -> 0 | E29: Recipe Pending | F29: Seasoned baby octopus sushi
A30: Chuka Idako Tsumami | B30: ='Sushi - Sashimi Stall'!E87 -> 0 | C30: ='Sushi - Sashimi Stall'!E90 | D30: =IFERROR(B30/C30,0) -> 0 | E30: Recipe Pending | F30: Seasoned baby octopus salad
A31: Unagi Sushi Roll | B31: ='Sushi - Sashimi Stall'!E105 -> 215487.52 | C31: 80000 | D31: =IFERROR(B31/C31,0) -> 2.693594 | E31: Recipe Pending | F31: Sushi roll with avocado,cucumber and crispy on top with grilled unagi
A32: Crispy Salmon Roll | B32: ='Sushi - Sashimi Stall'!E123 -> 0 | C32: 80000 | D32: =IFERROR(B32/C32,0) -> 0 | E32: Recipe Pending | F32: Sushi roll inside crabstick,avocado and crispy on top aburi salmon
A33: Salmon Cured Yuzu | B33: ='Sushi - Sashimi Stall'!E141 -> 0 | C33: ='Sushi - Sashimi Stall'!E144 | D33: =IFERROR(B33/C33,0) -> 0 | E33: Recipe Pending | F33: Salmon Cured served with yuzu dressing
A34: Tuna Cured Yuzu | B34: ='Sushi - Sashimi Stall'!E159 -> 0 | C34: ='Sushi - Sashimi Stall'!E162 | D34: =IFERROR(B34/C34,0) -> 0 | E34: Recipe Pending | F34: Tuna cured served with yuzu dressing
A35: Maguro Maki | B35: ='Sushi - Sashimi Stall'!E177 -> 0 | C35: ='Sushi - Sashimi Stall'!E180 | D35: =IFERROR(B35/C35,0) -> 0 | E35: Recipe Pending | F35: small roll sushi with tuna
A36: Salmon Maki | B36: ='Sushi - Sashimi Stall'!E195 -> 0 | C36: 85000 | D36: =IFERROR(B36/C36,0) -> 0 | E36: Recipe Pending | F36: small roll sushi with salmon
A37: Salmon Philadelpia | B37: ='Sushi - Sashimi Stall'!E213 -> 168193.77 | C37: 85000 | D37: =IFERROR(B37/C37,0) -> 1.9787503 | E37: Recipe Pending | F37: sushi roll wrapped with salmon and inside cream cheese and cucumber
A38: Crispy Temaki Sushi | B38: ='Sushi - Sashimi Stall'!E231 -> 168834.11 | C38: ='Sushi - Sashimi Stall'!E234 | D38: =IFERROR(B38/C38,0) -> 0 | E38: Recipe Pending | F38: crispy corn sushi with spicy tuna mayo and cucumber
A39: California Roll | B39: ='Sushi - Sashimi Stall'!E249 -> 168193.77 | C39: 75000 | D39: =IFERROR(B39/C39,0) -> 2.2425836 | E39: Recipe Pending | F39: avocado,cucumber,crab stick and tobiko served with creamy mayonaise
A41: Bakery Stall | B41: =IFERROR(AVERAGE(B42:B54),0) -> 5328.0886 | C41: =IFERROR(AVERAGE(C42:C54),0) -> 17222.222 | D41: =IFERROR(B41/C41,0) -> 0.30937289
A42: Doughnut Matcha | B42: ='Bakery Stall'!E15 -> 3044.9101 | C42: ='Bakery Stall'!E18 -> 15000 | D42: =IFERROR(B42/C42,0) -> 0.20299401 | E42: Assembly Qty Pending | F42: glazed with matcha cream and garnish
A43: Doughnut Hojicha | B43: ='Bakery Stall'!E33 -> 3134.7598 | C43: ='Bakery Stall'!E36 -> 15000 | D43: =IFERROR(B43/C43,0) -> 0.20898399 | E43: Assembly Qty Pending | F43: glazed with matcha cream and garnish
A44: Shuffle Pancake Mochi Chocolate | B44: ='Bakery Stall'!E51 -> 6205.7488 | C44: ='Bakery Stall'!E54 | D44: =IFERROR(B44/C44,0) -> 0 | E44: Assembly Qty Pending | F44: Mochi blanket with chocolate sauce
...

Sheet Yakitori Stall
A1: Yakitori Stall
A2: Negima
A3: Element | B3: UOM | C3: Element Cost/(g) | D3: Portion Used | E3: Value /pcs | F3: Major Step | G3: Units
A4: Ayam Paha Fillet | B4: GR | C4: =IFERROR(VLOOKUP(A4,'Market List'!$B:$F,5,FALSE),0) -> 40 | D4: 85 | E4: =IFERROR(C4*D4,0) -> 3400 | F4: Prep: Potong 3 @28 gr/pcs. pastikan ayam paha fillet , kulit ayam, batang daun bawang pun sudah terpotong sesuai ukuran
A5: Kulit Ayam | B5: GR | C5: =IFERROR(VLOOKUP(A5,'Market List'!$B:$F,5,FALSE),0) -> 30 | D5: 15 | E5: =IFERROR(C5*D5,0) -> 450 | F5: Prep: Potong 3 @5 gr/pcs; gunakan untuk menutupi setiap ayam. langkah awal,tusuk batang daun bawang setelah itu tusuk kulit ayam 1 sisi dulu, tusuk ayam paha fillet secara melengkung setelah itu lapisi dengan tusuk kulit ayam disisi ujungnya.
A6: Daun Bawang | B6: GR | C6: =IFERROR(VLOOKUP(A6,'Market List'!$B:$F,5,FALSE),0) -> 20 | D6: 12 | E6: =IFERROR(C6*D6,0) -> 240 | F6: Prep: Gunakan batang; potong ukuran 2 ruas jari (3 pcs). lakukan secara terus menerus dengan rasio batang daun bawang, ayam+ayam+batang daun bawang+terakhir ayam lagi.
A7: Yakitori Butter WIP | B7: GR | C7: ='WIP FOOD'!$B$691 -> 76.564551 | D7: 35 | E7: =IFERROR(C7*D7,0) -> 2679.7593 | F7: pastikan arang sudah siap dengan suhu tinggi, tempatkan tusukan negima tepat diatas arang, oleskan yakitori butter di kedua sisi negima, focus dan teliti ketika bakar
A8: Tusuk Sate Yakitori 18cm | B8: PCS | C8: =IFERROR(VLOOKUP(A8,'Market List'!$B:$F,5,FALSE),0) -> 217.92 | D8: 1 | E8: =IFERROR(C8*D8,0) -> 217.92 | F8: dapatkan teksture negima warna dengan golden brown dan sedikit char gosong, untuk olesan yakitori butter nya bisa dilakukan 3-4 kali olesan sekali bakar.
A9: Furikake WIP | B9: GR | C9: ='WIP FOOD'!$B$218 -> 362.72092 | D9: 1 | E9: =IFERROR(C9*D9,0) -> 362.72092
A10: Onion Pickles | B10: GR | C10: =IFERROR(VLOOKUP(A10,'Market List'!$B:$F,5,FALSE),0) -> 91.76 | D10: 2 | E10: =IFERROR(C10*D10,0) -> 183.52
A11: Cucumber Pickles WIP | B11: GR | C11: ='WIP FOOD'!$B$119 -> 13.97688 | D11: 3 | E11: =IFERROR(C11*D11,0) -> 41.930639
A12: Boxes, packaging, etc. | E12: 0
A13: Direct Cost | E13: =SUM(E4:E12) -> 7575.8509 | F13: Source: SULU-bdg FoodTesting.xlsx - ITEM SALES RECIPE
A14: Indirect Cost | E14: =E13*15% -> 1136.3776 | F14: Status: Recipe Available
A15: Cost of Goods Sold (COGS) | E15: =E13+E14 -> 8712.2285
A16: Margin | E16: =IF(E18>0,E18-E15,0) -> 11287.772
A17: Div COGS | E17: =IFERROR(E15/E18,0) -> 0.43561142
A18: Selling Price | E18: 20000
A20: Tsukune
A21: Element | B21: UOM | C21: Element Cost/(g) | D21: Portion Used | E21: Value /pcs | F21: Major Step | G21: Units
A22: Minched Beef WIP | B22: GR | C22: ='WIP FOOD'!$B$372 -> 94.388263 | D22: 60 | E22: =IFERROR(C22*D22,0) -> 5663.2958 | F22: Siapkan Adonan Tsukune, Tusuk menggunakan tusukan yakitori 2 pcs dengan cara tusukan satenya dibuat menyamping kedalam masing masing, kepal kepal tsukune pada tusukan
A23: Yakitori Butter WIP | B23: GR | C23: ='WIP FOOD'!$B$691 -> 76.564551 | D23: 35 | E23: =IFERROR(C23*D23,0) -> 2679.7593 | F23: tempatkan pada tumpuan hibachi,oleskan yakitori butter di kedua sisi,fokus dan teliti ketika bakar hingga golden brown dan sedikit char gosong,
A24: Tusuk Sate Yakitori 18cm | B24: PCS | C24: =IFERROR(VLOOKUP(A24,'Market List'!$B:$F,5,FALSE),0) -> 217.92 | D24: 2 | E24: =IFERROR(C24*D24,0) -> 435.84 | F24: untuk olesan yakitori butter nya bisa dilakukan 3-4 kali olesan sekali bakar, dengan bulak balik tsukune
A25: Furikake WIP | B25: GR | C25: ='WIP FOOD'!$B$218 -> 362.72092 | D25: 1 | E25: =IFERROR(C25*D25,0) -> 362.72092
A26: Onion Pickles | B26: GR | C26: =IFERROR(VLOOKUP(A26,'Market List'!$B:$F,5,FALSE),0) -> 91.76 | D26: 2 | E26: =IFERROR(C26*D26,0) -> 183.52
A27: Cucumber Pickles WIP | B27: GR | C27: ='WIP FOOD'!$B$119 -> 13.97688 | D27: 3 | E27: =IFERROR(C27*D27,0) -> 41.930639
C28: 0 | E28: =IFERROR(C28*D28,0) -> 0
C29: 0 | E29: =IFERROR(C29*D29,0) -> 0
A30: Boxes, packaging, etc. | E30: 0
A31: Direct Cost | E31: =SUM(E22:E30) -> 9367.0666 | F31: Source: SULU-bdg FoodTesting.xlsx - ITEM SALES RECIPE
A32: Indirect Cost | E32: =E31*15% -> 1405.06 | F32: Status: Recipe Available
A33: Cost of Goods Sold (COGS) | E33: =E31+E32 -> 10772.127
A34: Margin | E34: =IF(E36>0,E36-E33,0) -> 14227.873
A35: Div COGS | E35: =IFERROR(E33/E36,0) -> 0.43088507
A36: Selling Price | E36: 25000
A38: Torikawa
A39: Element | B39: UOM | C39: Element Cost/(g) | D39: Portion Used | E39: Value /pcs | F39: Major Step | G39: Units
A40: Kulit Ayam | B40: GR | C40: =IFERROR(VLOOKUP(A40,'Market List'!$B:$F,5,FALSE),0) -> 30 | D40: 50 | E40: =IFERROR(C40*D40,0) -> 1500 | F40: Potong kecil kecil kulit ayam yang sudah direbus,lalu tusukan pada tusuk sate satu persatu hingga ke ujung rapat dan lebar.pastikan arang sudah siap dengan suhu tinggi,tempatkan
A41: Yakitori Butter WIP | B41: GR | C41: ='WIP FOOD'!$B$691 -> 76.564551 | D41: 35 | E41: =IFERROR(C41*D41,0) -> 2679.7593 | F41: tusukan torikawa diatas arang,oleskan yakitori butter di kedua sisi torikawa,fokus dan teliti ketika bakar dapatkan tekstur torikawa dengan golden brown dan sedikit char gosong,
A42: Tusuk Sate Yakitori 18cm | B42: PCS | C42: =IFERROR(VLOOKUP(A42,'Market List'!$B:$F,5,FALSE),0) -> 217.92 | D42: 1 | E42: =IFERROR(C42*D42,0) -> 217.92 | F42: untuk olesan yakitori butter nya bisa dilakukan 3-4 kali olesan sekali bakar.
...

Sheet Teppanyaki Stall 
A1: Teppanyaki Stall
A2: Takoyaki
A3: Element | B3: UOM | C3: Element Cost/(g) | D3: Portion Used | E3: Value /pcs | F3: Major Step | G3: Units
A4: Adonan Takoyaki WIP | B4: Pcs | C4: ='WIP FOOD'!$B$28 -> 546.0819 | D4: 5 | E4: =IFERROR(C4*D4,0) -> 2730.4095 | F4: Recipe detail belum ditemukan pada ITEM SALES RECIPE / PDF yang tersedia.
A5: Udang Vaname | B5: Gr | C5: =IFERROR(VLOOKUP(A5,'Market List'!$B:$F,5,FALSE),0) -> 148 | D5: 25 | E5: =IFERROR(C5*D5,0) -> 3700
A6: Cumi | C6: =IFERROR(VLOOKUP(A6,'Market List'!$B:$F,5,FALSE),0) -> 185 | D6: 25 | E6: =IFERROR(C6*D6,0) -> 4625
A7: Aonori | B7: gr | C7: =IFERROR(VLOOKUP(A7,'Market List'!$B:$F,5,FALSE),0) -> 496 | D7: 1 | E7: =IFERROR(C7*D7,0) -> 496
A8: Daun Bawang | B8: gr | C8: =IFERROR(VLOOKUP(A8,'Market List'!$B:$F,5,FALSE),0) -> 20 | D8: 5 | E8: =IFERROR(C8*D8,0) -> 100
A9: Tanuki | B9: gr | C9: =IFERROR(VLOOKUP(A9,'Market List'!$B:$F,5,FALSE),0) -> 0 | D9: 20 | E9: =IFERROR(C9*D9,0) -> 0
A10: Okonomiyaki Sauce WIP | C10: ='WIP FOOD'!$B$452 -> 74.822755 | D10: 15 | E10: =IFERROR(C10*D10,0) -> 1122.3413
A11: Mayonaise | C11: =IFERROR(VLOOKUP(A11,'Market List'!$B:$F,5,FALSE),0) -> 72.3 | D11: 15 | E11: =IFERROR(C11*D11,0) -> 1084.5
A12: Katsuobushi | B12: gr | C12: =IFERROR(VLOOKUP(A12,'Market List'!$B:$F,5,FALSE),0) -> 478.3989 | D12: 1 | E12: =IFERROR(C12*D12,0) -> 478.3989
A15: Boxes, packaging, etc. | E15: 0
A16: Direct Cost | E16: =SUM(E4:E15) -> 14336.65 | F16: Source: -
A17: Indirect Cost | E17: =E16*15% -> 2150.4975 | F17: Status: Recipe Pending
A18: Cost of Goods Sold (COGS) | E18: =E16+E17 -> 16487.147
A19: Margin | E19: =IF(E21>0,E21-E18,0) -> 43512.853
A20: Div COGS | E20: =IFERROR(E18/E21,0) -> 0.27478579
A21: Selling Price | E21: 60000
A23: Yasai Itame
A24: Element | B24: UOM | C24: Element Cost/(g) | D24: Portion Used | E24: Value /pcs | F24: Major Step | G24: Units
A25: Kol | B25: GR | C25: =IFERROR(VLOOKUP(A25,'Market List'!$B:$F,5,FALSE),0) -> 13 | E25: =IFERROR(C25*D25,0) -> 0 | F25: Recipe detail belum ditemukan pada ITEM SALES RECIPE / PDF yang tersedia.
A26: Wortel | B26: GR | C26: =IFERROR(VLOOKUP(A26,'Market List'!$B:$F,5,FALSE),0) -> 20 | E26: =IFERROR(C26*D26,0) -> 0
A27: paprika merah | B27: GR | C27: =IFERROR(VLOOKUP(A27,'Market List'!$B:$F,5,FALSE),0) -> 0 | E27: =IFERROR(C27*D27,0) -> 0
A28: paprica hijau | B28: GR | C28: =IFERROR(VLOOKUP(A28,'Market List'!$B:$F,5,FALSE),0) -> 65 | E28: =IFERROR(C28*D28,0) -> 0
A29: Bawang Bombay | B29: GR | C29: =IFERROR(VLOOKUP(A29,'Market List'!$B:$F,5,FALSE),0) -> 35 | E29: =IFERROR(C29*D29,0) -> 0
A30: Beef Shortplate Slice | B30: GR | C30: =IFERROR(VLOOKUP(A30,'Market List'!$B:$F,5,FALSE),0) -> 135 | E30: =IFERROR(C30*D30,0) -> 0
E31: =IFERROR(C31*D31,0) -> 0
E32: =IFERROR(C32*D32,0) -> 0
A33: Boxes, packaging, etc. | E33: 0
A34: Direct Cost | E34: =SUM(E25:E33) -> 0 | F34: Source: -
A35: Indirect Cost | E35: =E34*15% -> 0 | F35: Status: Recipe Pending
A36: Cost of Goods Sold (COGS) | E36: =E34+E35 -> 0
A37: Margin | E37: =IF(E39>0,E39-E36,0) -> 65000
A38: Div COGS | E38: =IFERROR(E36/E39,0) -> 0
A39: Selling Price | E39: 65000
A41: Ika Sugatayaki
A42: Element | B42: UOM | C42: Element Cost/(g) | D42: Portion Used | E42: Value /pcs | F42: Major Step | G42: Units
A43: Cumi | C43: =IFERROR(VLOOKUP(A43,'Market List'!$B:$F,5,FALSE),0) -> 185 | D43: 100 | E43: =IFERROR(C43*D43,0) -> 18500 | F43: Recipe detail belum ditemukan pada ITEM SALES RECIPE / PDF yang tersedia.
E44: =IFERROR(C44*D44,0) -> 0
...

Sheet Dumpling Stall
A1: Dumpling Stall
A2: Okonomiyaki Gyoza
A3: Element | B3: UOM | C3: Element Cost/(g) | D3: Portion Used | E3: Value /pcs | F3: Major Step | G3: Units
A4: Adonan Gyoza WIP | B4: PCS | C4: ='WIP FOOD'!$B$3 -> 598.22 | D4: 5 | E4: =IFERROR(C4*D4,0) -> 2991.1 | F4: Panaskan Teplon dan tuangkan minyak goreng, masukan gyoza dengan lipatan diatas, gunakan api kecil terlebih dahulu dan tutup dengan teplon 1 nya guna uap panas biar merata
A5: Gyoza Tuile WIP | B5: PCS | C5: ='WIP FOOD'!$B$229 -> 168.975 | D5: 1 | E5: =IFERROR(C5*D5,0) -> 168.975 | F5: setelah kurang lebih 3 menit, berikan air secukupnya gunakan teknik masak kukus agar gyoza matang merata dan tutup kembali, dan gunakan api sedang.
A6: Okonomiyaki Sauce WIP | B6: GR | C6: ='WIP FOOD'!$B$452 -> 74.822755 | D6: 50 | E6: =IFERROR(C6*D6,0) -> 3741.1378 | F6: setelah dirasa cukup dari segi warna sedikit char dari bagian bawah gyoza, angkat dan tata diatas plate, tempatkan tuille di bagian atas gyoza hingga menutupi seluruh gyozanya
A7: Mayonaise | B7: GR | C7: =IFERROR(VLOOKUP(A7,'Market List'!$B:$F,5,FALSE),0) -> 72.3 | D7: 30 | E7: =IFERROR(C7*D7,0) -> 2169 | F7: berikan sauce okonomiyaki pada bagian tuille nya setelah itu mayonaise, berikan katsuobushi dan taburan aonori.
A8: Katsuobushi | B8: GR | C8: =IFERROR(VLOOKUP(A8,'Market List'!$B:$F,5,FALSE),0) -> 478.3989 | D8: 2 | E8: =IFERROR(C8*D8,0) -> 956.7978
A9: Aonori | B9: GR | C9: =IFERROR(VLOOKUP(A9,'Market List'!$B:$F,5,FALSE),0) -> 496 | D9: 1 | E9: =IFERROR(C9*D9,0) -> 496
A10: Minyak Goreng | B10: ML | C10: =IFERROR(VLOOKUP(A10,'Market List'!$B:$F,5,FALSE),0) -> 21.944444 | D10: 20 | E10: =IFERROR(C10*D10,0) -> 438.88889
E11: =IFERROR(C11*D11,0) -> 0
A12: Boxes, packaging, etc. | E12: 0
A13: Direct Cost | E13: =SUM(E4:E12) -> 10961.899 | F13: Source: SULU-bdg FoodTesting.xlsx - ITEM SALES RECIPE
A14: Indirect Cost | E14: =E13*15% -> 1644.2849 | F14: Status: Recipe Available
A15: Cost of Goods Sold (COGS) | E15: =E13+E14 -> 12606.184
A16: Margin | E16: =IF(E18>0,E18-E15,0) -> 22393.816
A17: Div COGS | E17: =IFERROR(E15/E18,0) -> 0.3601767
A18: Selling Price | E18: 35000
A20: Slider Gyoza Mentai
A21: Element | B21: UOM | C21: Element Cost/(g) | D21: Portion Used | E21: Value /pcs | F21: Major Step | G21: Units
A22: Adonan Gyoza WIP | B22: PCS | C22: ='WIP FOOD'!$B$3 -> 598.22 | D22: 5 | E22: =IFERROR(C22*D22,0) -> 2991.1 | F22: Goreng Gyoza dengan temprature normal 150-170 derajat, pastikan selesai dengan warna golden brown.
A23: Mentaiko Mayo WIP | B23: GR | C23: ='WIP FOOD'!$B$362 -> 163.41546 | D23: 30 | E23: =IFERROR(C23*D23,0) -> 4902.4638 | F23: setelah dapat dipastikan matang, tata di piring dengan memanjang rapi, berikan sauce mentaiko terlebih dahulu, taburi furikake dan terakhir berikan garnish ditata memanjang
A24: Furikake WIP | B24: GR | C24: ='WIP FOOD'!$B$218 -> 362.72092 | D24: 2 | E24: =IFERROR(C24*D24,0) -> 725.44184 | F24: mengikuti persentasi gyoza nya. terakhir tempatkan lime sichimi nya di bagian atas gyoza
A25: Garnish daun bawang dan paprika | B25: GR | C25: =IFERROR(VLOOKUP(A25,'Market List'!$B:$F,5,FALSE),0) -> 0 | D25: 2 | E25: =IFERROR(C25*D25,0) -> 0
A26: Lime Sichimi | B26: GR | C26: =IFERROR(VLOOKUP(A26,'Market List'!$B:$F,5,FALSE),0) -> 351.66667 | D26: 5 | E26: =IFERROR(C26*D26,0) -> 1758.3333
E27: =IFERROR(C27*D27,0) -> 0
E28: =IFERROR(C28*D28,0) -> 0
E29: =IFERROR(C29*D29,0) -> 0
A30: Boxes, packaging, etc. | E30: 0
A31: Direct Cost | E31: =SUM(E22:E30) -> 10377.339 | F31: Source: SULU-bdg FoodTesting.xlsx - ITEM SALES RECIPE
A32: Indirect Cost | E32: =E31*15% -> 1556.6008 | F32: Status: Recipe Available
A33: Cost of Goods Sold (COGS) | E33: =E31+E32 -> 11933.94
A34: Margin | E34: =IF(E36>0,E36-E33,0) -> 23066.06
A35: Div COGS | E35: =IFERROR(E33/E36,0) -> 0.34096971
A36: Selling Price | E36: 35000
A38: Spicy Tteokboki Gyoza
A39: Element | B39: UOM | C39: Element Cost/(g) | D39: Portion Used | E39: Value /pcs | F39: Major Step | G39: Units
A40: Adonan Gyoza WIP | B40: PCS | C40: ='WIP FOOD'!$B$3 -> 598.22 | D40: 5 | E40: =IFERROR(C40*D40,0) -> 2991.1 | F40: Panaskan Teplon dan tuangkan minyak goreng, masukan gyoza dengan lipatan diatas, gunakan api kecil terlebih dahulu dan tutup dengan teplon 1 nya guna uap panas biar merata
A41: Minyak Goreng | B41: ML | C41: =IFERROR(VLOOKUP(A41,'Market List'!$B:$F,5,FALSE),0) -> 21.944444 | D41: 20 | E41: =IFERROR(C41*D41,0) -> 438.88889 | F41: setelah kurang lebih 3 menit, berikan air secukupnya gunakan teknik masak kukus agar gyoza matang merata dan tutup kembali, dan gunakan api sedang.
A42: Tteokbokki Sauce WIP | B42: GR | C42: ='WIP FOOD'!$B$650 -> 80.31259 | D42: 120 | E42: =IFERROR(C42*D42,0) -> 9637.5108 | F42: Panaskan Sauce tteokbokki hingga mendidih dan panas merata, tuang pada bagian plate, angkat gyoza yang sudah dirasa cukup matang, dan tata pada bagian atas tteokbokki saucenya
...

Sheet Sushi - Sashimi Stall
A1: Sushi - Sashimi Stall
A2: Tamagoyaki Mentai
A3: Element | B3: UOM | C3: Element Cost/(g) | D3: Portion Used | E3: Value /pcs | F3: Major Step | G3: Units
A4: Adonan Tamagoyaki WIP | B4: PCS | C4: ='WIP FOOD'!$B$41 -> 1405.0439 | D4: 3 | E4: =IFERROR(C4*D4,0) -> 4215.1317 | F4: Recipe detail belum ditemukan pada ITEM SALES RECIPE / PDF yang tersedia.
A5: Mentaiko Mayo WIP | B5: GR | C5: ='WIP FOOD'!$B$362 -> 163.41546 | D5: 20 | E5: =IFERROR(C5*D5,0) -> 3268.3092
A6: Tobiko Orange | B6: ML | C6: =IFERROR(VLOOKUP(A6,'Market List'!$B:$F,5,FALSE),0) -> 0 | D6: 5 | E6: =IFERROR(C6*D6,0) -> 0
B7: GR | E7: =IFERROR(C7*D7,0) -> 0
E8: =IFERROR(C8*D8,0) -> 0
E9: =IFERROR(C9*D9,0) -> 0
E10: =IFERROR(C10*D10,0) -> 0
E11: =IFERROR(C11*D11,0) -> 0
A12: Boxes, packaging, etc. | E12: 0
A13: Direct Cost | E13: =SUM(E4:E12) -> 7483.4409 | F13: Source: -
A14: Indirect Cost | E14: =E13*15% -> 1122.5161 | F14: Status: Recipe Pending
A15: Cost of Goods Sold (COGS) | E15: =E13+E14 -> 8605.9571
A16: Margin | E16: =IF(E18>0,E18-E15,0) -> 0
A17: Div COGS | E17: =IFERROR(E15/E18,0) -> 0
A18: Selling Price
A20: Tuna Wasabi Mayo Taco
A21: Element | B21: UOM | C21: Element Cost/(g) | D21: Portion Used | E21: Value /pcs | F21: Major Step | G21: Units
A22: Tuna Saku | B22: GR | C22: =IFERROR(VLOOKUP(A22,'Market List'!$B:$F,5,FALSE),0) -> 0 | D22: 50 | E22: =IFERROR(C22*D22,0) -> 0 | F22: Recipe detail belum ditemukan pada ITEM SALES RECIPE / PDF yang tersedia.
A23: Mayonaise | B23: GR | C23: =IFERROR(VLOOKUP(A23,'Market List'!$B:$F,5,FALSE),0) -> 72.3 | D23: 100 | E23: =IFERROR(C23*D23,0) -> 7230
A24: Nori Sheets | B24: SHEET | C24: =IFERROR(VLOOKUP(A24,'Market List'!$B:$F,5,FALSE),0) -> 2741.6667 | D24: 1 | E24: =IFERROR(C24*D24,0) -> 2741.6667
A25: tobiko hitam | B25: GR | C25: =IFERROR(VLOOKUP(A25,'Market List'!$B:$F,5,FALSE),0) -> 0 | D25: 20 | E25: =IFERROR(C25*D25,0) -> 0
A26: Daun Bawang | B26: GR | C26: =IFERROR(VLOOKUP(A26,'Market List'!$B:$F,5,FALSE),0) -> 20 | D26: 5 | E26: =IFERROR(C26*D26,0) -> 100
A27: adonan tempura | B27: GR | C27: =IFERROR(VLOOKUP(A27,'Market List'!$B:$F,5,FALSE),0) -> 0 | D27: 10 | E27: =IFERROR(C27*D27,0) -> 0
E28: =IFERROR(C28*D28,0) -> 0
E29: =IFERROR(C29*D29,0) -> 0
A30: Boxes, packaging, etc. | E30: 0
A31: Direct Cost | E31: =SUM(E22:E30) -> 10071.667 | F31: Source: -
A32: Indirect Cost | E32: =E31*15% -> 1510.75 | F32: Status: Recipe Pending
A33: Cost of Goods Sold (COGS) | E33: =E31+E32 -> 11582.417
A34: Margin | E34: =IF(E36>0,E36-E33,0) -> 0
A35: Div COGS | E35: =IFERROR(E33/E36,0) -> 0
A36: Selling Price
A38: Unagi Nigiri
A39: Element | B39: UOM | C39: Element Cost/(g) | D39: Portion Used | E39: Value /pcs | F39: Major Step | G39: Units
A40: UNAGI | B40: GR | C40: =IFERROR(VLOOKUP(A40,'Market List'!$B:$F,5,FALSE),0) -> 0 | D40: 48 | E40: =IFERROR(C40*D40,0) -> 0 | F40: Recipe detail belum ditemukan pada ITEM SALES RECIPE / PDF yang tersedia.
A41: Nasi Sushi WIP | B41: GR | C41: ='WIP FOOD'!$B$421 -> 811.36364 | D41: 52 | E41: =IFERROR(C41*D41,0) -> 42190.909
A42: NORI IKETAN | C42: =IFERROR(VLOOKUP(A42,'Market List'!$B:$F,5,FALSE),0) -> 0 | D42: 40 | E42: =IFERROR(C42*D42,0) -> 0
...

Sheet Bakery Stall
A1: Bakery Stall
A2: Doughnut Matcha
A3: Element | B3: UOM | C3: Element Cost/(g) | D3: Portion Used | E3: Value /pcs | F3: Major Step | G3: Units
A4: Donat / Bomboloni WIP | B4: PCS | C4: ='WIP FOOD'!$B$150 -> 1131.0914 | D4: 1 | E4: =IFERROR(C4*D4,0) -> 1131.0914
A5: Matcha Filling WIP | B5: GR | C5: ='WIP FOOD'!$B$329 -> 68.93893 | D5: 22 | E5: =IFERROR(C5*D5,0) -> 1516.6565
E6: =IFERROR(C6*D6,0) -> 0
E7: =IFERROR(C7*D7,0) -> 0
E8: =IFERROR(C8*D8,0) -> 0
E9: =IFERROR(C9*D9,0) -> 0
E10: =IFERROR(C10*D10,0) -> 0
E11: =IFERROR(C11*D11,0) -> 0
A12: Boxes, packaging, etc. | E12: 0
A13: Direct Cost | E13: =SUM(E4:E12) -> 2647.7479 | F13: Source: Uploaded Bakery Recipe PDFs
A14: Indirect Cost | E14: =E13*15% -> 397.16219 | F14: Status: Assembly Qty Pending
A15: Cost of Goods Sold (COGS) | E15: =E13+E14 -> 3044.9101
A16: Margin | E16: =IF(E18>0,E18-E15,0) -> 11955.09
A17: Div COGS | E17: =IFERROR(E15/E18,0) -> 0.20299401
A18: Selling Price | E18: 15000
A20: Doughnut Hojicha
A21: Element | B21: UOM | C21: Element Cost/(g) | D21: Portion Used | E21: Value /pcs | F21: Major Step | G21: Units
A22: Donat / Bomboloni WIP | B22: PCS | C22: ='WIP FOOD'!$B$150 -> 1131.0914 | D22: 1 | E22: =IFERROR(C22*D22,0) -> 1131.0914
A23: Hojicha Filling WIP | B23: GR | C23: ='WIP FOOD'!$B$250 -> 72.490303 | D23: 22 | E23: =IFERROR(C23*D23,0) -> 1594.7867
E24: =IFERROR(C24*D24,0) -> 0
E25: =IFERROR(C25*D25,0) -> 0
E26: =IFERROR(C26*D26,0) -> 0
E27: =IFERROR(C27*D27,0) -> 0
E28: =IFERROR(C28*D28,0) -> 0
E29: =IFERROR(C29*D29,0) -> 0
A30: Boxes, packaging, etc. | E30: 0
A31: Direct Cost | E31: =SUM(E22:E30) -> 2725.8781 | F31: Source: Uploaded Bakery Recipe PDFs
A32: Indirect Cost | E32: =E31*15% -> 408.88172 | F32: Status: Assembly Qty Pending
A33: Cost of Goods Sold (COGS) | E33: =E31+E32 -> 3134.7598
A34: Margin | E34: =IF(E36>0,E36-E33,0) -> 11865.24
A35: Div COGS | E35: =IFERROR(E33/E36,0) -> 0.20898399
A36: Selling Price | E36: 15000
A38: Shuffle Pancake Mochi Chocolate
A39: Element | B39: UOM | C39: Element Cost/(g) | D39: Portion Used | E39: Value /pcs | F39: Major Step | G39: Units
A40: Souffle Pancake WIP | B40: PORTION | C40: ='WIP FOOD'!$B$531 -> 2380.0482 | D40: 1 | E40: =IFERROR(C40*D40,0) -> 2380.0482
A41: Mochi Plain WIP | B41: PCS | C41: ='WIP FOOD'!$B$401 -> 41.783225 | D41: 30 | E41: =IFERROR(C41*D41,0) -> 1253.4968
A42: Chocolate Sauce WIP | B42: GR | C42: ='WIP FOOD'!$B$109 -> 76.641669 | D42: 23 | E42: =IFERROR(C42*D42,0) -> 1762.7584
...

Sheet Burger - sandwiches Stall
A1: Burger - sandwiches Stall
A2: Gyuniku Burger
A3: Element | B3: UOM | C3: Element Cost/(g) | D3: Portion Used | E3: Value /pcs | F3: Major Step | G3: Units
A4: Brioche Burger Bun WIP | B4: PCS | C4: ='WIP FOOD'!$B$51 -> 3998.7741 | D4: 75 | E4: =IFERROR(C4*D4,0) -> 299908.06 | F4: Recipe detail belum ditemukan pada ITEM SALES RECIPE / PDF yang tersedia.
A5: BEEF NOODLE | B5: GR | C5: =IFERROR(VLOOKUP(A5,'Market List'!$B:$F,5,FALSE),0) -> 0 | D5: 20 | E5: =IFERROR(C5*D5,0) -> 0
E6: =IFERROR(C6*D6,0) -> 0
E7: =IFERROR(C7*D7,0) -> 0
E8: =IFERROR(C8*D8,0) -> 0
E9: =IFERROR(C9*D9,0) -> 0
E10: =IFERROR(C10*D10,0) -> 0
E11: =IFERROR(C11*D11,0) -> 0
A12: Boxes, packaging, etc. | E12: 0
A13: Direct Cost | E13: =SUM(E4:E12) -> 299908.06 | F13: Source: -
A14: Indirect Cost | E14: =E13*15% -> 44986.209 | F14: Status: Recipe Pending
A15: Cost of Goods Sold (COGS) | E15: =E13+E14 -> 344894.27
A16: Margin | E16: =IF(E18>0,E18-E15,0) -> 0
A17: Div COGS | E17: =IFERROR(E15/E18,0) -> 0
A18: Selling Price
A20: Chicken Namban Burger
A21: Element | B21: UOM | C21: Element Cost/(g) | D21: Portion Used | E21: Value /pcs | F21: Major Step | G21: Units
A22: Brioche Burger Bun WIP | B22: PCS | C22: =IFERROR(VLOOKUP(A22,'Market List'!$B:$F,5,FALSE),0) -> 3998.7741 | D22: 1 | E22: =IFERROR(C22*D22,0) -> 3998.7741 | F22: Recipe detail belum ditemukan pada ITEM SALES RECIPE / PDF yang tersedia.
A23: Soy Chicken WIP | B23: GR | C23: =IFERROR(VLOOKUP(A23,'Market List'!$B:$F,5,FALSE),0) -> 1225.7319 | D23: 2 | E23: =IFERROR(C23*D23,0) -> 2451.4637
A24: Namban Sauce WIP | B24: ML | C24: ='WIP FOOD'!$B$411 -> 37.76749 | D24: 15 | E24: =IFERROR(C24*D24,0) -> 566.51235
A25: Egg Tartar WIP | B25: GR | C25: ='WIP FOOD'!$B$207 -> 45.457392 | D25: 30 | E25: =IFERROR(C25*D25,0) -> 1363.7218
A26: Daun Bawang | B26: GR | C26: =IFERROR(VLOOKUP(A26,'Market List'!$B:$F,5,FALSE),0) -> 20 | D26: 3 | E26: =IFERROR(C26*D26,0) -> 60
E27: =IFERROR(C27*D27,0) -> 0
E28: =IFERROR(C28*D28,0) -> 0
E29: =IFERROR(C29*D29,0) -> 0
A30: Boxes, packaging, etc. | E30: 0
A31: Direct Cost | E31: =SUM(E22:E30) -> 8440.4719 | F31: Source: -
A32: Indirect Cost | E32: =E31*15% -> 1266.0708 | F32: Status: Recipe Pending
A33: Cost of Goods Sold (COGS) | E33: =E31+E32 -> 9706.5427
A34: Margin | E34: =IF(E36>0,E36-E33,0) -> 0
A35: Div COGS | E35: =IFERROR(E33/E36,0) -> 0
A36: Selling Price
A38: Tempura Kimchi Hotdog
A39: Element | B39: UOM | C39: Element Cost/(g) | D39: Portion Used | E39: Value /pcs | F39: Major Step | G39: Units
A40: Udang Tempura | B40: PCS | C40: =IFERROR(VLOOKUP(A40,'Market List'!$B:$F,5,FALSE),0) -> 132 | D40: 15 | E40: =IFERROR(C40*D40,0) -> 1980 | F40: Recipe detail belum ditemukan pada ITEM SALES RECIPE / PDF yang tersedia.
A41: Kol Kimchi WIP | B41: GR | C41: ='WIP FOOD'!$B$288 -> 29.984632 | D41: 10 | E41: =IFERROR(C41*D41,0) -> 299.84632
A42: Brioche Hot Dog WIP | B42: PCS | C42: ='WIP FOOD'!$B$712 -> 2525.5416 | D42: 1 | E42: =IFERROR(C42*D42,0) -> 2525.5416
...

Sheet Agemono - Frying Section Stall
A1: Agemono - Frying Section Stall
A2: Chicken Namban
A3: Element | B3: UOM | C3: Element Cost/(g) | D3: Portion Used | E3: Value /pcs | F3: Major Step | G3: Units
A4: Soy Chicken WIP | B4: PCS | C4: ='WIP FOOD'!$B$543 -> 1225.7319 | D4: 3 | E4: =IFERROR(C4*D4,0) -> 3677.1956 | F4: Pastikan minyak deepfrying panas dengan temp 170 derajat celcius
A5: Egg Tartar WIP | B5: GR | C5: ='WIP FOOD'!$B$207 -> 45.457392 | D5: 40 | E5: =IFERROR(C5*D5,0) -> 1818.2957 | F5: siap kan tepung tapioka, masukan 3 potong ayam kedalam tapioka dan baluri secara menyeluruh dan tercover dengan cukup
A6: Namban Sauce WIP | B6: ML | C6: ='WIP FOOD'!$B$411 -> 37.76749 | D6: 50 | E6: =IFERROR(C6*D6,0) -> 1888.3745 | F6: masukan ayam yang sudah terbaluri tapioka, goreng selama kurang lebih 2 menit, lalu angkat ayam dan resting kurang lebih 1 menit
A7: Furikake WIP | B7: PINCHED | C7: ='WIP FOOD'!$B$218 -> 362.72092 | D7: 1 | E7: =IFERROR(C7*D7,0) -> 362.72092 | F7: setelah ayam resting, goreng kembali ayam kurang lebih selama 1,5 menit. setelah selesai langsung baluri ayam dengan sauce namban
A8: Daun Bawang slice | B8: PINCHED | C8: =IFERROR(VLOOKUP(A8,'Market List'!$B:$F,5,FALSE),0) -> 20 | D8: 1 | E8: =IFERROR(C8*D8,0) -> 20 | F8: plating 3 ayam tadi yang sudah di goreng dan terbaluti namban sauce, berikan eggtartar mayo dibagian atas ayamnya,berikan
A9: Tepung Tapioka | B9: GR | C9: =IFERROR(VLOOKUP(A9,'Market List'!$B:$F,5,FALSE),0) -> 16 | D9: 100 | E9: =IFERROR(C9*D9,0) -> 1600 | F9: taburan furikake dan daun bawang diatas eggtartar.
E10: =IFERROR(C10*D10,0) -> 0
E11: =IFERROR(C11*D11,0) -> 0
A12: Boxes, packaging, etc. | E12: 0
A13: Direct Cost | E13: =SUM(E4:E12) -> 9366.5867 | F13: Source: SULU-bdg FoodTesting.xlsx - ITEM SALES RECIPE
A14: Indirect Cost | E14: =E13*15% -> 1404.988 | F14: Status: Recipe Available
A15: Cost of Goods Sold (COGS) | E15: =E13+E14 -> 10771.575
A16: Margin | E16: =IF(E18>0,E18-E15,0) -> 29228.425
A17: Div COGS | E17: =IFERROR(E15/E18,0) -> 0.26928937
A18: Selling Price | E18: 40000
A20: Signature Torikaraage
A21: Element | B21: UOM | C21: Element Cost/(g) | D21: Portion Used | E21: Value /pcs | F21: Major Step | G21: Units
A22: Soy Chicken WIP | B22: PCS | C22: ='WIP FOOD'!$B$543 -> 1225.7319 | D22: 3 | E22: =IFERROR(C22*D22,0) -> 3677.1956 | F22: Pastikan minyak deepfrying panas dengan temp 170 derajat celcius
A23: Tapioka charcoal | B23: GR | C23: =IFERROR(VLOOKUP(A23,'Market List'!$B:$F,5,FALSE),0) -> 0 | D23: 100 | E23: =IFERROR(C23*D23,0) -> 0 | F23: siap kan tepung tapioka charcoal, masukan 3 potong ayam kedalam tapioka dan baluri secara menyeluruh dan tercover dengan cukup
A24: Okonomiyaki Sauce WIP | B24: GR | C24: ='WIP FOOD'!$B$452 -> 74.822755 | D24: 30 | E24: =IFERROR(C24*D24,0) -> 2244.6827 | F24: masukan ayam yang sudah terbaluri tapioka, goreng selama kurang lebih 2 menit, lalu angkat ayam dan resting kurang lebih 1 menit
A25: Furikake WIP | B25: GR | C25: ='WIP FOOD'!$B$218 -> 362.72092 | D25: 2 | E25: =IFERROR(C25*D25,0) -> 725.44184 | F25: setelah ayam resting, goreng kembali ayam kurang lebih selama 1,5 menit.
A26: Kol Kimchi WIP | B26: GR | C26: ='WIP FOOD'!$B$288 -> 29.984632 | D26: 30 | E26: =IFERROR(C26*D26,0) -> 899.53896 | F26: Plating karaage, berikan sauce okonomiyaki pada bagian ayam, taburi furikake, tempatkan kol kimchi setelah furikake, dan taburi daun bawang
A27: Daun Bawang | B27: GR | C27: =IFERROR(VLOOKUP(A27,'Market List'!$B:$F,5,FALSE),0) -> 20 | D27: 4 | E27: =IFERROR(C27*D27,0) -> 80
E28: =IFERROR(C28*D28,0) -> 0
E29: =IFERROR(C29*D29,0) -> 0
A30: Boxes, packaging, etc. | E30: 0
A31: Direct Cost | E31: =SUM(E22:E30) -> 7626.8591 | F31: Source: SULU-bdg FoodTesting.xlsx - ITEM SALES RECIPE
A32: Indirect Cost | E32: =E31*15% -> 1144.0289 | F32: Status: Recipe Available
A33: Cost of Goods Sold (COGS) | E33: =E31+E32 -> 8770.8879
A34: Margin | E34: =IF(E36>0,E36-E33,0) -> 31229.112
A35: Div COGS | E35: =IFERROR(E33/E36,0) -> 0.2192722
A36: Selling Price | E36: 40000
A38: Cheese Minched Katsu
A39: Element | B39: UOM | C39: Element Cost/(g) | D39: Portion Used | E39: Value /pcs | F39: Major Step | G39: Units
A40: Minched Beef WIP | B40: PCS | C40: ='WIP FOOD'!$B$372 -> 94.388263 | D40: 100 | E40: =IFERROR(C40*D40,0) -> 9438.8263 | F40: Goreng Minched katsu yang sudah diprep dengan suhu minyak standart 170 derajat kurang lebih 2 menit,lalu istirahatkan 1 menit dan goreng kembali di 2menit lagi
A41: Okonomiyaki Sauce WIP | B41: GR | C41: ='WIP FOOD'!$B$452 -> 74.822755 | D41: 30 | E41: =IFERROR(C41*D41,0) -> 2244.6827 | F41: angkat dan tiriskan minched katsunya.
A42: Wasabi mayo | B42: GR | C42: =IFERROR(VLOOKUP(A42,'Market List'!$B:$F,5,FALSE),0) -> 627.77778 | D42: 10 | E42: =IFERROR(C42*D42,0) -> 6277.7778 | F42: siapkan piring/rice paper, berikan wasabi mayo untuk bagian pertama, setelah itu minched katsunya, berikan sauce okonomiyaki, setelah itu furikake
...

Sheet Rice bowl Stall
A1: Rice bowl Stall
A2: Gyutan Donburi
A3: Element | B3: UOM | C3: Element Cost/(g) | D3: Portion Used | E3: Value /pcs | F3: Major Step | G3: Units
A4: Gyutan Marinasi | B4: GR | C4: =IFERROR(VLOOKUP(A4,'Market List'!$B:$F,5,FALSE),0) -> 0 | D4: 80 | E4: =IFERROR(C4*D4,0) -> 0 | F4: Panaskan teflon terlebih dahulu, masukan butter dan bawang bombay tumis terlebih dahulu, masukan gyutan yang sudah dimarinasi sauce yakiniku, lalu masak hingga matang
A5: Rice | B5: GR | C5: =IFERROR(VLOOKUP(A5,'Market List'!$B:$F,5,FALSE),0) -> 41.26 | D5: 160 | E5: =IFERROR(C5*D5,0) -> 6601.6 | F5: namun dipastikan tidak gosong dari bagian sauce nya gunakan api sedang dan terus di tumis.
A6: Furikake WIP | B6: GR | C6: ='WIP FOOD'!$B$218 -> 362.72092 | D6: 3 | E6: =IFERROR(C6*D6,0) -> 1088.1628 | F6: tuang nasi kedalam mangkuk, taburi furikake terlebih dahulu, tata rapih gyutan yang sudah dimasak, tempatkan onsen egg dibagian tengahnya, taburi daun bawang pada final
A7: Telur | B7: PCS | C7: =IFERROR(VLOOKUP(A7,'Market List'!$B:$F,5,FALSE),0) -> 1785.7143 | D7: 1 | E7: =IFERROR(C7*D7,0) -> 1785.7143 | F7: Untuk chili oilnya diberikan on the side
A8: Daun Bawang | B8: GR | C8: =IFERROR(VLOOKUP(A8,'Market List'!$B:$F,5,FALSE),0) -> 20 | D8: 3 | E8: =IFERROR(C8*D8,0) -> 60
A9: Chili Oil WIP | B9: GR | C9: ='WIP FOOD'!$B$72 -> 120.11858 | D9: 15 | E9: =IFERROR(C9*D9,0) -> 1801.7786
A10: Butter | B10: GR | C10: =IFERROR(VLOOKUP(A10,'Market List'!$B:$F,5,FALSE),0) -> 140 | D10: 8 | E10: =IFERROR(C10*D10,0) -> 1120
A11: Bawang Bombay | B11: GR | C11: =IFERROR(VLOOKUP(A11,'Market List'!$B:$F,5,FALSE),0) -> 35 | D11: 8 | E11: =IFERROR(C11*D11,0) -> 280
A12: Boxes, packaging, etc. | E12: 0
A13: Direct Cost | E13: =SUM(E4:E12) -> 12737.256 | F13: Source: SULU-bdg FoodTesting.xlsx - ITEM SALES RECIPE
A14: Indirect Cost | E14: =E13*15% -> 1910.5884 | F14: Status: Recipe Available
A15: Cost of Goods Sold (COGS) | E15: =E13+E14 -> 14647.844
A16: Margin | E16: =IF(E18>0,E18-E15,0) -> 60352.156
A17: Div COGS | E17: =IFERROR(E15/E18,0) -> 0.19530459
A18: Selling Price | E18: 75000
A20: Beef Yakiniku Bowl
A21: Element | B21: UOM | C21: Element Cost/(g) | D21: Portion Used | E21: Value /pcs | F21: Major Step | G21: Units
A22: Beef marinasi yakiniku | B22: GR | C22: =IFERROR(VLOOKUP(A22,'Market List'!$B:$F,5,FALSE),0) -> 0 | D22: 80 | E22: =IFERROR(C22*D22,0) -> 0 | F22: Panaskan teflon terlebih dahulu, masukan butter dan bawang bombay tumis terlebih dahulu, masukan beef yang sudah dimarinasi sauce yakiniku, lalu masak hingga matang
A23: Rice | B23: GR | C23: =IFERROR(VLOOKUP(A23,'Market List'!$B:$F,5,FALSE),0) -> 41.26 | D23: 160 | E23: =IFERROR(C23*D23,0) -> 6601.6 | F23: namun dipastikan tidak gosong dari bagian sauce nya gunakan api sedang dan terus di tumis.
A24: Furikake WIP | B24: GR | C24: ='WIP FOOD'!$B$218 -> 362.72092 | D24: 3 | E24: =IFERROR(C24*D24,0) -> 1088.1628 | F24: tuang nasi kedalam mangkuk, taburi furikake terlebih dahulu, tata rapih gyutan yang sudah dimasak, tempatkan onsen egg dibagian tengahnya, taburi daun bawang pada final
A25: Telur | B25: PCS | C25: =IFERROR(VLOOKUP(A25,'Market List'!$B:$F,5,FALSE),0) -> 1785.7143 | D25: 1 | E25: =IFERROR(C25*D25,0) -> 1785.7143 | F25: Untuk chili oilnya diberikan on the side
A26: Daun Bawang | B26: GR | C26: =IFERROR(VLOOKUP(A26,'Market List'!$B:$F,5,FALSE),0) -> 20 | D26: 3 | E26: =IFERROR(C26*D26,0) -> 60
A27: Chili Oil WIP | B27: GR | C27: ='WIP FOOD'!$B$72 -> 120.11858 | D27: 15 | E27: =IFERROR(C27*D27,0) -> 1801.7786
A28: Butter | B28: GR | C28: =IFERROR(VLOOKUP(A28,'Market List'!$B:$F,5,FALSE),0) -> 140 | D28: 8 | E28: =IFERROR(C28*D28,0) -> 1120
A29: Bawang Bombay | B29: GR | C29: =IFERROR(VLOOKUP(A29,'Market List'!$B:$F,5,FALSE),0) -> 35 | D29: 8 | E29: =IFERROR(C29*D29,0) -> 280
A30: Boxes, packaging, etc. | E30: 0
A31: Direct Cost | E31: =SUM(E22:E30) -> 12737.256 | F31: Source: SULU-bdg FoodTesting.xlsx - ITEM SALES RECIPE
A32: Indirect Cost | E32: =E31*15% -> 1910.5884 | F32: Status: Recipe Available
A33: Cost of Goods Sold (COGS) | E33: =E31+E32 -> 14647.844
A34: Margin | E34: =IF(E36>0,E36-E33,0) -> 55352.156
A35: Div COGS | E35: =IFERROR(E33/E36,0) -> 0.20925492
A36: Selling Price | E36: 70000
A38: Smoked Duck Donburi
A39: Element | B39: UOM | C39: Element Cost/(g) | D39: Portion Used | E39: Value /pcs | F39: Major Step | G39: Units
A40: Smocked Duck | B40: GR | C40: =IFERROR(VLOOKUP(A40,'Market List'!$B:$F,5,FALSE),0) -> 254.5 | D40: 80 | E40: =IFERROR(C40*D40,0) -> 20360 | F40: Panaskan teflon terlebih dahulu, masukan butter dan bawang bombay tumis terlebih dahulu, masukan bebek yang sudah di slice, berikan sauce yakiniku, lalu masak hingga matang
A41: Rice | B41: GR | C41: =IFERROR(VLOOKUP(A41,'Market List'!$B:$F,5,FALSE),0) -> 41.26 | D41: 160 | E41: =IFERROR(C41*D41,0) -> 6601.6 | F41: namun dipastikan tidak gosong dari bagian sauce nya gunakan api sedang dan terus di tumis.
A42: Furikake WIP | B42: GR | C42: ='WIP FOOD'!$B$218 -> 362.72092 | D42: 3 | E42: =IFERROR(C42*D42,0) -> 1088.1628 | F42: tuang nasi kedalam mangkuk, taburi furikake terlebih dahulu, tata rapih smoked duck yang sudah dimasak, tempatkan onsen egg dibagian tengahnya, taburi daun bawang pada final
...

Sheet Ramen - Noodles Stall
A1: Ramen - Noodles Stall
A2: Aka Miso Ramen
A3: Element | B3: UOM | C3: Element Cost/(g) | D3: Portion Used | E3: Value /pcs | F3: Major Step | G3: Units
A4: Ramen | B4: GR | C4: =IFERROR(VLOOKUP(A4,'Market List'!$B:$F,5,FALSE),0) -> 28.070175 | D4: 80 | E4: =IFERROR(C4*D4,0) -> 2245.614 | F4: Pastikan boiler mendidih dengan sempurna, masukan ramen noodles dan berikan timer 1 menit. siapkan mangkok ramen, masukan garlic oil dan lada
A5: Miso Soup WIP | B5: ML | C5: ='WIP FOOD'!$B$391 -> 8.7389381 | D5: 240 | E5: =IFERROR(C5*D5,0) -> 2097.3451 | F5: panaskan miso soup menggunakan sauce pot dan pastikan mendidih maksimal, matikan kompor, tuang sesuai takaran yang dibutuhkan, lalu angkat ramen kalau sudah selesai timernya
A6: Garlic Oil | B6: GR | C6: =IFERROR(VLOOKUP(A6,'Market List'!$B:$F,5,FALSE),0) -> 86 | D6: 1 | E6: =IFERROR(C6*D6,0) -> 86 | F6: kocok kocok dulu untuk membuang sisa air dari boiler tadi, dan masukan ramen kedalam mangkoknya. berikan semua topping dengan cara ditata rapih dengan posisi menggunung
A7: Lada Putih | B7: GR | C7: =IFERROR(VLOOKUP(A7,'Market List'!$B:$F,5,FALSE),0) -> 200 | D7: 0.5 | E7: =IFERROR(C7*D7,0) -> 100 | F7: namun tidak menutupi satu sama lain topping nya
A8: Chili Oil WIP | B8: GR | C8: ='WIP FOOD'!$B$72 -> 120.11858 | D8: 35 | E8: =IFERROR(C8*D8,0) -> 4204.1502
A9: Soy Chicken WIP | B9: GR | C9: ='WIP FOOD'!$B$543 -> 1225.7319 | D9: 28 | E9: =IFERROR(C9*D9,0) -> 34320.492
A10: Smoked Duck Slice | B10: GR | C10: =IFERROR(VLOOKUP(A10,'Market List'!$B:$F,5,FALSE),0) -> 254.5 | D10: 10 | E10: =IFERROR(C10*D10,0) -> 2545 | F10: Prep: Grill; 1 slice.
A11: Jukut | B11: GR | C11: =IFERROR(VLOOKUP(A11,'Market List'!$B:$F,5,FALSE),0) -> 0 | D11: 4 | E11: =IFERROR(C11*D11,0) -> 0
A12: Daun Bawang | B12: GR | C12: =IFERROR(VLOOKUP(A12,'Market List'!$B:$F,5,FALSE),0) -> 20 | D12: 4 | E12: =IFERROR(C12*D12,0) -> 80
A13: Telur Omega | B13: BUTIR | C13: =IFERROR(VLOOKUP(A13,'Market List'!$B:$F,5,FALSE),0) -> 3600 | D13: 0.5 | E13: =IFERROR(C13*D13,0) -> 1800
A14: Boxes, packaging, etc. | E14: 0
A15: Direct Cost | E15: =SUM(E4:E14) -> 47478.602 | F15: Source: SULU-bdg FoodTesting.xlsx - ITEM SALES RECIPE
A16: Indirect Cost | E16: =E15*15% -> 7121.7902 | F16: Status: Recipe Available
A17: Cost of Goods Sold (COGS) | E17: =E15+E16 -> 54600.392
A18: Margin | E18: =IF(E20>0,E20-E17,0) -> 0
A19: Div Margin | E19: =IFERROR(E17/E20,0) -> 0
A20: Selling Price
A22: Spicy Goma Ramen
A23: Element | B23: UOM | C23: Element Cost/(g) | D23: Portion Used | E23: Value /pcs | F23: Major Step | G23: Units
A24: Ramen | B24: GR | C24: =IFERROR(VLOOKUP(A24,'Market List'!$B:$F,5,FALSE),0) -> 28.070175 | D24: 80 | E24: =IFERROR(C24*D24,0) -> 2245.614 | F24: Pastikan boiler mendidih dengan sempurna, masukan ramen noodles dan berikan timer 1 menit. siapkan mangkok ramen, tuang goma ramen sauce,garlic oil,royco dan lada
A25: Chicken Broth | B25: ML | C25: =IFERROR(VLOOKUP(A25,'Market List'!$B:$F,5,FALSE),0) -> 0 | D25: 240 | E25: =IFERROR(C25*D25,0) -> 0 | F25: panaskan broth menggunakan sauce pot dan pastikan mendidih maksimal, matikan kompor, tuang sesuai takaran yang dibutuhkan, lalu angkat ramen kalau sudah selesai timernya
A26: Spicy Goma Sauce WIP | B26: ML | C26: ='WIP FOOD'!$B$553 -> 45.940387 | D26: 30 | E26: =IFERROR(C26*D26,0) -> 1378.2116 | F26: kocok kocok dulu untuk membuang sisa air dari boiler tadi, dan masukan ramen kedalam mangkoknya. berikan semua topping dengan cara ditata rapih dengan posisi menggunung
A27: Royco | B27: GR | C27: =IFERROR(VLOOKUP(A27,'Market List'!$B:$F,5,FALSE),0) -> 43.181818 | D27: 1 | E27: =IFERROR(C27*D27,0) -> 43.181818 | F27: namun tidak menutupi satu sama lain topping nya
A28: Garlic Oil | B28: GR | C28: =IFERROR(VLOOKUP(A28,'Market List'!$B:$F,5,FALSE),0) -> 86 | D28: 1 | E28: =IFERROR(C28*D28,0) -> 86
A29: Lada Putih | B29: GR | C29: =IFERROR(VLOOKUP(A29,'Market List'!$B:$F,5,FALSE),0) -> 200 | D29: 0.5 | E29: =IFERROR(C29*D29,0) -> 100
A30: Smoked Duck Slice | B30: GR | C30: =IFERROR(VLOOKUP(A30,'Market List'!$B:$F,5,FALSE),0) -> 254.5 | D30: 30 | E30: =IFERROR(C30*D30,0) -> 7635 | F30: Prep: Grill; 3 slice.
A31: Jukut | B31: GR | C31: =IFERROR(VLOOKUP(A31,'Market List'!$B:$F,5,FALSE),0) -> 0 | D31: 4 | E31: =IFERROR(C31*D31,0) -> 0
A32: Daun Bawang | B32: GR | C32: =IFERROR(VLOOKUP(A32,'Market List'!$B:$F,5,FALSE),0) -> 20 | D32: 4 | E32: =IFERROR(C32*D32,0) -> 80
A33: Telur Omega | B33: BUTIR | C33: =IFERROR(VLOOKUP(A33,'Market List'!$B:$F,5,FALSE),0) -> 3600 | D33: 0.5 | E33: =IFERROR(C33*D33,0) -> 1800
A34: Chili Oil WIP | B34: GR | C34: ='WIP FOOD'!$B$72 -> 120.11858 | D34: 35 | E34: =IFERROR(C34*D34,0) -> 4204.1502
A35: Boxes, packaging, etc. | E35: 0
A36: Direct Cost | E36: =SUM(E24:E35) -> 17572.158 | F36: Source: SULU-bdg FoodTesting.xlsx - ITEM SALES RECIPE
A37: Indirect Cost | E37: =E36*15% -> 2635.8236 | F37: Status: Recipe Available
A38: Cost of Goods Sold (COGS) | E38: =E36+E37 -> 20207.981
A39: Margin | E39: =IF(E41>0,E41-E38,0) -> 0
A40: Div Margin | E40: =IFERROR(E38/E41,0) -> 0
A41: Selling Price
...

Sheet Udon - Noodles Stall
A1: Udon - Noodles Stall
A2: Udon Carbonara
A3: Element | B3: UOM | C3: Element Cost/(g) | D3: Portion Used | E3: Value /pcs | F3: Major Step | G3: Units
A4: Udon | B4: GR | C4: =IFERROR(VLOOKUP(A4,'Market List'!$B:$F,5,FALSE),0) -> 394.4 | D4: 180 | E4: =IFERROR(C4*D4,0) -> 70992 | F4: Pastikan boiler mendidih dengan sempurna, masukan ramen noodles dan berikan timer 1 menit. siapkan sauce pot , tuang mazesoba sauce,garlic oil,royco,curry , lada dan butter
A5: Bawang Bombay | C5: =IFERROR(VLOOKUP(A5,'Market List'!$B:$F,5,FALSE),0) -> 35 | E5: =IFERROR(C5*D5,0) -> 0 | F5: Prep: Dice. Angkat ramen, masukan ke sauce pot yang sudah ada saucenya, aduk secara gentle dan merata bagus, tuang ke mangkuk secara rapih (center)
A6: Butter | C6: =IFERROR(VLOOKUP(A6,'Market List'!$B:$F,5,FALSE),0) -> 140 | E6: =IFERROR(C6*D6,0) -> 0 | F6: tata rapih semua topping dan tidak menutupi topping satu sama lain.
A7: Cooking Cream | C7: =IFERROR(VLOOKUP(A7,'Market List'!$B:$F,5,FALSE),0) -> 69 | E7: =IFERROR(C7*D7,0) -> 0
E8: =IFERROR(C8*D8,0) -> 0
E9: =IFERROR(C9*D9,0) -> 0
E10: =IFERROR(C10*D10,0) -> 0
E11: =IFERROR(C11*D11,0) -> 0
A12: Boxes, packaging, etc. | E12: 0
A13: Direct Cost | E13: =SUM(E4:E12) -> 70992 | F13: Source: SULU-bdg FoodTesting.xlsx - ITEM SALES RECIPE
A14: Indirect Cost | E14: =E13*15% -> 10648.8 | F14: Status: Recipe Available
A15: Cost of Goods Sold (COGS) | E15: =E13+E14 -> 81640.8
A16: Margin | E16: =IF(E18>0,E18-E15,0) -> 0
A17: Div Margin | E17: =IFERROR(E15/E18,0) -> 0
A18: Selling Price
A20: Gyutan Udon
A21: Element | B21: UOM | C21: Element Cost/(g) | D21: Portion Used | E21: Value /pcs | F21: Major Step | G21: Units
E22: =IFERROR(C22*D22,0) -> 0 | F22: Recipe detail belum ditemukan pada ITEM SALES RECIPE / PDF yang tersedia.
E23: =IFERROR(C23*D23,0) -> 0
E24: =IFERROR(C24*D24,0) -> 0
E25: =IFERROR(C25*D25,0) -> 0
E26: =IFERROR(C26*D26,0) -> 0
E27: =IFERROR(C27*D27,0) -> 0
E28: =IFERROR(C28*D28,0) -> 0
E29: =IFERROR(C29*D29,0) -> 0
A30: Boxes, packaging, etc. | E30: 0
A31: Direct Cost | E31: =SUM(E22:E30) -> 0 | F31: Source: -
A32: Indirect Cost | E32: =E31*15% -> 0 | F32: Status: Recipe Pending
A33: Cost of Goods Sold (COGS) | E33: =E31+E32 -> 0
A34: Margin | E34: =IF(E36>0,E36-E33,0) -> 0
A35: Div Margin | E35: =IFERROR(E33/E36,0) -> 0
A36: Selling Price
A38: Beefu Udon
A39: Element | B39: UOM | C39: Element Cost/(g) | D39: Portion Used | E39: Value /pcs | F39: Major Step | G39: Units
E40: =IFERROR(C40*D40,0) -> 0 | F40: Recipe detail belum ditemukan pada ITEM SALES RECIPE / PDF yang tersedia.
E41: =IFERROR(C41*D41,0) -> 0
E42: =IFERROR(C42*D42,0) -> 0
...

Sheet Japanese Poridge Stall
A1: Japanese Poridge Stall
A2: Okayu Beef
A3: Element | B3: UOM | C3: Element Cost/(g) | D3: Portion Used | E3: Value /pcs | F3: Major Step | G3: Units
E4: =IFERROR(C4*D4,0) -> 0 | F4: Recipe detail belum ditemukan pada ITEM SALES RECIPE / PDF yang tersedia.
E5: =IFERROR(C5*D5,0) -> 0
E6: =IFERROR(C6*D6,0) -> 0
E7: =IFERROR(C7*D7,0) -> 0
E8: =IFERROR(C8*D8,0) -> 0
E9: =IFERROR(C9*D9,0) -> 0
E10: =IFERROR(C10*D10,0) -> 0
E11: =IFERROR(C11*D11,0) -> 0
A12: Boxes, packaging, etc. | E12: 0
A13: Direct Cost | E13: =SUM(E4:E12) -> 0 | F13: Source: -
A14: Indirect Cost | E14: =E13*15% -> 0 | F14: Status: Recipe Pending
A15: Cost of Goods Sold (COGS) | E15: =E13+E14 -> 0
A16: Margin | E16: =IF(E18>0,E18-E15,0) -> 0
A17: Div Margin | E17: =IFERROR(E15/E18,0) -> 0
A18: Selling Price
A20: Smoked Duck Okayu
A21: Element | B21: UOM | C21: Element Cost/(g) | D21: Portion Used | E21: Value /pcs | F21: Major Step | G21: Units
E22: =IFERROR(C22*D22,0) -> 0 | F22: Recipe detail belum ditemukan pada ITEM SALES RECIPE / PDF yang tersedia.
E23: =IFERROR(C23*D23,0) -> 0
E24: =IFERROR(C24*D24,0) -> 0
E25: =IFERROR(C25*D25,0) -> 0
E26: =IFERROR(C26*D26,0) -> 0
E27: =IFERROR(C27*D27,0) -> 0
E28: =IFERROR(C28*D28,0) -> 0
E29: =IFERROR(C29*D29,0) -> 0
A30: Boxes, packaging, etc. | E30: 0
A31: Direct Cost | E31: =SUM(E22:E30) -> 0 | F31: Source: -
A32: Indirect Cost | E32: =E31*15% -> 0 | F32: Status: Recipe Pending
A33: Cost of Goods Sold (COGS) | E33: =E31+E32 -> 0
A34: Margin | E34: =IF(E36>0,E36-E33,0) -> 0
A35: Div Margin | E35: =IFERROR(E33/E36,0) -> 0
A36: Selling Price
A38: Tori Okayu
A39: Element | B39: UOM | C39: Element Cost/(g) | D39: Portion Used | E39: Value /pcs | F39: Major Step | G39: Units
E40: =IFERROR(C40*D40,0) -> 0 | F40: Recipe detail belum ditemukan pada ITEM SALES RECIPE / PDF yang tersedia.
E41: =IFERROR(C41*D41,0) -> 0
E42: =IFERROR(C42*D42,0) -> 0
...

Sheet Yakimono - Griiled Stall
A1: Yakimono - Griiled Stall
A2: Beefu Hikiniku
A3: Element | B3: UOM | C3: Element Cost/(g) | D3: Portion Used | E3: Value /pcs | F3: Major Step | G3: Units
E4: =IFERROR(C4*D4,0) -> 0 | F4: Recipe detail belum ditemukan pada ITEM SALES RECIPE / PDF yang tersedia.
E5: =IFERROR(C5*D5,0) -> 0
E6: =IFERROR(C6*D6,0) -> 0
E7: =IFERROR(C7*D7,0) -> 0
E8: =IFERROR(C8*D8,0) -> 0
E9: =IFERROR(C9*D9,0) -> 0
E10: =IFERROR(C10*D10,0) -> 0
E11: =IFERROR(C11*D11,0) -> 0
A12: Boxes, packaging, etc. | E12: 0
A13: Direct Cost | E13: =SUM(E4:E12) -> 0 | F13: Source: -
A14: Indirect Cost | E14: =E13*15% -> 0 | F14: Status: Recipe Pending
A15: Cost of Goods Sold (COGS) | E15: =E13+E14 -> 0
A16: Margin | E16: =IF(E18>0,E18-E15,0) -> 0
A17: Div Margin | E17: =IFERROR(E15/E18,0) -> 0
A18: Selling Price
A20: Salmon Don
A21: Element | B21: UOM | C21: Element Cost/(g) | D21: Portion Used | E21: Value /pcs | F21: Major Step | G21: Units
E22: =IFERROR(C22*D22,0) -> 0 | F22: Recipe detail belum ditemukan pada ITEM SALES RECIPE / PDF yang tersedia.
E23: =IFERROR(C23*D23,0) -> 0
E24: =IFERROR(C24*D24,0) -> 0
E25: =IFERROR(C25*D25,0) -> 0
E26: =IFERROR(C26*D26,0) -> 0
E27: =IFERROR(C27*D27,0) -> 0
E28: =IFERROR(C28*D28,0) -> 0
E29: =IFERROR(C29*D29,0) -> 0
A30: Boxes, packaging, etc. | E30: 0
A31: Direct Cost | E31: =SUM(E22:E30) -> 0 | F31: Source: -
A32: Indirect Cost | E32: =E31*15% -> 0 | F32: Status: Recipe Pending
A33: Cost of Goods Sold (COGS) | E33: =E31+E32 -> 0
A34: Margin | E34: =IF(E36>0,E36-E33,0) -> 0
A35: Div Margin | E35: =IFERROR(E33/E36,0) -> 0
A36: Selling Price
A38: Unagimeshi
A39: Element | B39: UOM | C39: Element Cost/(g) | D39: Portion Used | E39: Value /pcs | F39: Major Step | G39: Units
E40: =IFERROR(C40*D40,0) -> 0 | F40: Recipe detail belum ditemukan pada ITEM SALES RECIPE / PDF yang tersedia.
E41: =IFERROR(C41*D41,0) -> 0
E42: =IFERROR(C42*D42,0) -> 0
...

Sheet Onigiri Corner Stall
A1: Onigiri Corner Stall
A2: Onigiri Spicy Tuna
A3: Element | B3: UOM | C3: Element Cost/(g) | D3: Portion Used | E3: Value /pcs | F3: Major Step | G3: Units
E4: =IFERROR(C4*D4,0) -> 0 | F4: Recipe detail belum ditemukan pada ITEM SALES RECIPE / PDF yang tersedia.
E5: =IFERROR(C5*D5,0) -> 0
E6: =IFERROR(C6*D6,0) -> 0
E7: =IFERROR(C7*D7,0) -> 0
E8: =IFERROR(C8*D8,0) -> 0
E9: =IFERROR(C9*D9,0) -> 0
E10: =IFERROR(C10*D10,0) -> 0
E11: =IFERROR(C11*D11,0) -> 0
A12: Boxes, packaging, etc. | E12: 0
A13: Direct Cost | E13: =SUM(E4:E12) -> 0 | F13: Source: -
A14: Indirect Cost | E14: =E13*15% -> 0 | F14: Status: Recipe Pending
A15: Cost of Goods Sold (COGS) | E15: =E13+E14 -> 0
A16: Margin | E16: =IF(E18>0,E18-E15,0) -> 0
A17: Div Margin | E17: =IFERROR(E15/E18,0) -> 0
A18: Selling Price
A20: Cakalang Onigiri
A21: Element | B21: UOM | C21: Element Cost/(g) | D21: Portion Used | E21: Value /pcs | F21: Major Step | G21: Units
E22: =IFERROR(C22*D22,0) -> 0 | F22: Recipe detail belum ditemukan pada ITEM SALES RECIPE / PDF yang tersedia.
E23: =IFERROR(C23*D23,0) -> 0
E24: =IFERROR(C24*D24,0) -> 0
E25: =IFERROR(C25*D25,0) -> 0
E26: =IFERROR(C26*D26,0) -> 0
E27: =IFERROR(C27*D27,0) -> 0
E28: =IFERROR(C28*D28,0) -> 0
E29: =IFERROR(C29*D29,0) -> 0
A30: Boxes, packaging, etc. | E30: 0
A31: Direct Cost | E31: =SUM(E22:E30) -> 0 | F31: Source: -
A32: Indirect Cost | E32: =E31*15% -> 0 | F32: Status: Recipe Pending
A33: Cost of Goods Sold (COGS) | E33: =E31+E32 -> 0
A34: Margin | E34: =IF(E36>0,E36-E33,0) -> 0
A35: Div Margin | E35: =IFERROR(E33/E36,0) -> 0
A36: Selling Price
A38: Salmon Mayo Onigiri
A39: Element | B39: UOM | C39: Element Cost/(g) | D39: Portion Used | E39: Value /pcs | F39: Major Step | G39: Units
E40: =IFERROR(C40*D40,0) -> 0 | F40: Recipe detail belum ditemukan pada ITEM SALES RECIPE / PDF yang tersedia.
E41: =IFERROR(C41*D41,0) -> 0
E42: =IFERROR(C42*D42,0) -> 0
...

Sheet Market List
A1: MARKET LIST
A2: Category | B2: Ingredients | C2: UOM | D2: Weight (gr/ea/ml) | E2: Unit Cost | F2: Unit Price (g)
A3: Raw Material | B3: Kyuri/japanese cucumber | C3: GR | D3: 1000 | E3: 17500 | F3: =IFERROR(E3/D3,0) -> 17.5
A4: Raw Material | B4: Garam | C4: GR | D4: 500 | E4: 8000 | F4: =IFERROR(E4/D4,0) -> 16
A5: Raw Material | B5: Dry chili | C5: GR | D5: 1000 | E5: 140000 | F5: =IFERROR(E5/D5,0) -> 140
A6: Raw Material | B6: rice vinegar | C6: ML | D6: 600 | E6: 29300 | F6: =IFERROR(E6/D6,0) -> 48.833333
A7: Raw Material | B7: gula putih | C7: GR | D7: 1000 | E7: 18000 | F7: =IFERROR(E7/D7,0) -> 18
A8: Raw Material | B8: Sesame oil | C8: ML | D8: 620 | E8: 39000 | F8: =IFERROR(E8/D8,0) -> 62.903226
A9: Raw Material | B9: Air | C9: ML | D9: 18000 | E9: 56700 | F9: =IFERROR(E9/D9,0) -> 3.15
A10: Raw Material | B10: Telur rebus dan chopped | C10: GR | D10: 1000 | E10: 25000 | F10: =IFERROR(E10/D10,0) -> 25
A11: Raw Material | B11: Kewpie Mayonnaise | C11: GR | D11: 1000 | E11: 72300 | F11: =IFERROR(E11/D11,0) -> 72.3
A12: Raw Material | B12: Bawang Bombay | C12: GR | D12: 1000 | E12: 35000 | F12: =IFERROR(E12/D12,0) -> 35
A13: Raw Material | B13: Lada Putih | C13: GR | D13: 1000 | E13: 200000 | F13: =IFERROR(E13/D13,0) -> 200
A14: Raw Material | B14: Hondashi | C14: GR | D14: 1000 | E14: 155500 | F14: =IFERROR(E14/D14,0) -> 155.5
... A77: Raw Material | B77: Sawi | C77: GR | D77: 1000 | E77: 13000 | F77: =IFERROR(E77/D77,0) -> 13
A78: Raw Material | B78: Air Dashi | C78: ML | F78: =IFERROR(E78/D78,0) -> 0
A79: Raw Material | B79: Daging beef giling | C79: GR | D79: 1000 | E79: 113000 | F79: =IFERROR(E79/D79,0) -> 113
A80: Raw Material | B80: Oyster Sauce | C80: GR | D80: 770 | E80: 50000 | F80: =IFERROR(E80/D80,0) -> 64.935065
A81: Raw Material | B81: Cheese Cheddar | C81: GR | D81: 2000 | E81: 182100 | F81: =IFERROR(E81/D81,0) -> 91.05
A82: Raw Material | B82: Telur Pasar Curah | C82: BUTIR | D82: 14 | E82: 25000 | F82: =IFERROR(E82/D82,0) -> 1785.7143
A83: Raw Material | B83: Tepung roti (ditempat berbeda) | C83: KG | D83: 200 | E83: 23450 | F83: =IFERROR(E83/D83,0) -> 117.25
A84: Raw Material | B84: Tepung Segitiga biru | C84: GR | D84: 1000 | E84: 13000 | F84: =IFERROR(E84/D84,0) -> 13
A85: Raw Material | B85: Nasi Panas | C85: GR | F85: =IFERROR(E85/D85,0) -> 0
A86: Raw Material | B86: Pasta miso | C86: GR | D86: 1000 | E86: 46500 | F86: =IFERROR(E86/D86,0) -> 46.5
A87: Raw Material | B87: paprica hijau | C87: GR | D87: 1000 | E87: 65000 | F87: =IFERROR(E87/D87,0) -> 65
A88: Raw Material | B88: cabe hijau besar | C88: GR | D88: 1000 | E88: 38000 | F88: =IFERROR(E88/D88,0) -> 38
A89: Raw Material | B89: tomat hijau | C89: GR | D89: 1000 | E89: 20000 | F89: =IFERROR(E89/D89,0) -> 20
A90: Raw Material | B90: celeri steak | C90: GR | D90: 1000 | E90: 35000 | F90: =IFERROR(E90/D90,0) -> 35
A91: Raw Material | B91: minyak | C91: GR | D91: 18000 | E91: 395000 | F91: =IFERROR(E91/D91,0) -> 21.944444
A92: Raw Material | B92: terigu | C92: GR | D92: 1000 | E92: 14500 | F92: =IFERROR(E92/D92,0) -> 14.5
A93: Raw Material | B93: Shayou kikkoman | C93: GR | D93: 1600 | E93: 120000 | F93: =IFERROR(E93/D93,0) -> 75
A94: Raw Material | B94: Nasi | C94: KG | F94: =IFERROR(E94/D94,0) -> 0
A95: Raw Material | B95: Truffle Oil | C95: GR | D95: 250 | E95: 242950 | F95: =IFERROR(E95/D95,0) -> 971.8
A96: Raw Material | B96: Nori Sheets | C96: LEMBAR | D96: 60 | E96: 164500 | F96: =IFERROR(E96/D96,0) -> 2741.6667
A97: Raw Material | B97: Sichimi | C97: GR | D97: 300 | E97: 105500 | F97: =IFERROR(E97/D97,0) -> 351.66667
A98: Raw Material | B98: Telur Pasar | C98: PCS | D98: 14 | E98: 25000 | F98: =IFERROR(E98/D98,0) -> 1785.7143
A99: Raw Material | B99: Beef Shortplate Slice | C99: GR | D99: 1000 | E99: 135000 | F99: =IFERROR(E99/D99,0) -> 135
A100: Raw Material | B100: Paprika powder | C100: GR | D100: 1000 | E100: 82466 | F100: =IFERROR(E100/D100,0) -> 82.466
A101: Raw Material | B101: Jinten Powder | C101: GR | D101: 1000 | E101: 89900 | F101: =IFERROR(E101/D101,0) -> 89.9
A102: Raw Material | B102: Bulldog tonkotsu sauce | C102: GR | D102: 1800 | E102: 172700.46 | F102: =IFERROR(E102/D102,0) -> 95.9447
...

Sheet WIP FOOD
A1: WORK IN PROGRESS
A2: Semua Sub Menu / Sub-Recipe dan production base yang mendukung menu. Seluruh nama item menggunakan suffix WIP.
A3: Adonan Gyoza WIP | B3: =IFERROR(D15/D3,0) -> 598.22 | C3: Portion | D3: 120 | E3: Pcs
A4: Ingredients | B4: Use (g/ml/ea) | C4: Unit Price / Unit | D4: Price | E4: Major Step
A5: Ayam Giling | B5: 1000 | C5: =IFERROR(VLOOKUP(A5,'Market List'!$B:$F,5,FALSE),0) -> 45 | D5: =IFERROR(B5*C5,0) -> 45000 | E5: Aduk semua bahan pastikan tercampur dengan rata
A6: Daun Kucai | B6: 90 | C6: =IFERROR(VLOOKUP(A6,'Market List'!$B:$F,5,FALSE),0) -> 25 | D6: =IFERROR(B6*C6,0) -> 2250 | E6: Prep: Slice.
A7: Sawi Putih | B7: 750 | C7: =IFERROR(VLOOKUP(A7,'Market List'!$B:$F,5,FALSE),0) -> 13 | D7: =IFERROR(B7*C7,0) -> 9750 | E7: Prep: Chopped.
A8: Bawang Putih | B8: 12 | C8: =IFERROR(VLOOKUP(A8,'Market List'!$B:$F,5,FALSE),0) -> 45 | D8: =IFERROR(B8*C8,0) -> 540 | E8: Prep: Parut.
A9: Jahe | B9: 8 | C9: =IFERROR(VLOOKUP(A9,'Market List'!$B:$F,5,FALSE),0) -> 33 | D9: =IFERROR(B9*C9,0) -> 264 | E9: Prep: Parut.
A10: soy kikkoman | B10: 120 | C10: =IFERROR(VLOOKUP(A10,'Market List'!$B:$F,5,FALSE),0) -> 75 | D10: =IFERROR(B10*C10,0) -> 9000
A11: Lada putih bubuk | B11: 1 | C11: =IFERROR(VLOOKUP(A11,'Market List'!$B:$F,5,FALSE),0) -> 114.4 | D11: =IFERROR(B11*C11,0) -> 114.4
A12: Hondashi | B12: 20 | C12: =IFERROR(VLOOKUP(A12,'Market List'!$B:$F,5,FALSE),0) -> 155.5 | D12: =IFERROR(B12*C12,0) -> 3110
A13: Campignon | B13: 30 | C13: =IFERROR(VLOOKUP(A13,'Market List'!$B:$F,5,FALSE),0) -> 45 | D13: =IFERROR(B13*C13,0) -> 1350 | E13: Prep: Chopped.
A14: Curry Powder | B14: 3 | C14: =IFERROR(VLOOKUP(A14,'Market List'!$B:$F,5,FALSE),0) -> 136 | D14: =IFERROR(B14*C14,0) -> 408
A15: Element Cost | D15: =SUM(D5:D14) -> 71786.4 | E15: Source: SULU-bdg FoodTesting.xlsx - SUB-RECIPE CARD
